Ignoring exception in command None:
discord.ext.commands.errors.CommandNotFound: Command "countdown" is not found
Ignoring exception in command list:
Traceback (most recent call last):
  File "/home/pi/.local/lib/python3.7/site-packages/discord/ext/commands/core.py", line 83, in wrapped
    ret = await coro(*args, **kwargs)
  File "rentalbot.py", line 155, in list_timers
    await ctx.send('Timer list')
  File "/home/pi/.local/lib/python3.7/site-packages/discord/abc.py", line 856, in send
    data = await state.http.send_message(channel.id, content, tts=tts, embed=embed, nonce=nonce)
  File "/home/pi/.local/lib/python3.7/site-packages/discord/http.py", line 221, in request
    raise Forbidden(r, data)
discord.errors.Forbidden: 403 Forbidden (error code: 50013): Missing Permissions

The above exception was the direct cause of the following exception:

Traceback (most recent call last):
  File "/home/pi/.local/lib/python3.7/site-packages/discord/ext/commands/bot.py", line 892, in invoke
    await ctx.command.invoke(ctx)
  File "/home/pi/.local/lib/python3.7/site-packages/discord/ext/commands/core.py", line 797, in invoke
    await injected(*ctx.args, **ctx.kwargs)
  File "/home/pi/.local/lib/python3.7/site-packages/discord/ext/commands/core.py", line 92, in wrapped
    raise CommandInvokeError(exc) from exc
discord.ext.commands.errors.CommandInvokeError: Command raised an exception: Forbidden: 403 Forbidden (error code: 50013): Missing Permissions
SSL error in data received
protocol: <asyncio.sslproto.SSLProtocol object at 0x747a3fd0>
transport: <_SelectorSocketTransport fd=7 read=polling write=<idle, bufsize=0>>
Traceback (most recent call last):
  File "/usr/lib/python3.7/asyncio/sslproto.py", line 526, in data_received
    ssldata, appdata = self._sslpipe.feed_ssldata(data)
  File "/usr/lib/python3.7/asyncio/sslproto.py", line 207, in feed_ssldata
    self._sslobj.unwrap()
  File "/usr/lib/python3.7/ssl.py", line 767, in unwrap
    return self._sslobj.shutdown()
ssl.SSLError: [SSL: KRB5_S_INIT] application data after close notify (_ssl.c:2609)
Ignoring exception in command None:
discord.ext.commands.errors.CommandNotFound: Command "bot" is not found
Ignoring exception in command None:
discord.ext.commands.errors.CommandNotFound: Command "wreck" is not found
Ignoring exception in command None:
discord.ext.commands.errors.CommandNotFound: Command "bring" is not found
Ignoring exception in command None:
discord.ext.commands.errors.CommandNotFound: Command "give" is not found
~Logged in~
RentalBot
729469147037302895
~~~~~~~~~~~
~Logged in~
RentalBot
729469147037302895
~~~~~~~~~~~
Traceback (most recent call last):
  File "rentalbot.py", line 183, in <module>
    bot.run(token)
  File "/home/pi/.local/lib/python3.7/site-packages/discord/client.py", line 640, in run
    return future.result()
  File "/home/pi/.local/lib/python3.7/site-packages/discord/client.py", line 621, in runner
    await self.start(*args, **kwargs)
  File "/home/pi/.local/lib/python3.7/site-packages/discord/client.py", line 585, in start
    await self.connect(reconnect=reconnect)
  File "/home/pi/.local/lib/python3.7/site-packages/discord/client.py", line 499, in connect
    await self._connect()
  File "/home/pi/.local/lib/python3.7/site-packages/discord/client.py", line 463, in _connect
    await self.ws.poll_event()
  File "/home/pi/.local/lib/python3.7/site-packages/discord/gateway.py", line 471, in poll_event
    await self.received_message(msg)
  File "/home/pi/.local/lib/python3.7/site-packages/discord/gateway.py", line 425, in received_message
    func(data)
  File "/home/pi/.local/lib/python3.7/site-packages/discord/state.py", line 598, in parse_channel_update
    channel._update(guild, data)
  File "/home/pi/.local/lib/python3.7/site-packages/discord/channel.py", line 131, in _update
    self._fill_overwrites(data)
  File "/home/pi/.local/lib/python3.7/site-packages/discord/abc.py", line 294, in _fill_overwrites
    self._overwrites.append(_Overwrites(id=overridden_id, **overridden))
TypeError: __new__() got an unexpected keyword argument 'deny_new'
~Logged in~
RentalBot
729469147037302895
~~~~~~~~~~~
Ignoring exception in command None:
discord.ext.commands.errors.CommandNotFound: Command "just" is not found
Ignoring exception in command None:
discord.ext.commands.errors.CommandNotFound: Command "timer" is not found
Ignoring exception in command None:
discord.ext.commands.errors.CommandNotFound: Command "timer" is not found
Ignoring exception in command None:
discord.ext.commands.errors.CommandNotFound: Command "end" is not found
Ignoring exception in command None:
discord.ext.commands.errors.CommandNotFound: Command "~Fri" is not found
Ignoring exception in command None:
discord.ext.commands.errors.CommandNotFound: Command "~Fri" is not found
Ignoring exception in command None:
discord.ext.commands.errors.CommandNotFound: Command "~Fri" is not found
Ignoring exception in command None:
discord.ext.commands.errors.CommandNotFound: Command "timer" is not found
Ignoring exception in command None:
discord.ext.commands.errors.CommandNotFound: Command "timer" is not found
Ignoring exception in command None:
discord.ext.commands.errors.CommandNotFound: Command "time" is not found
Ignoring exception in command None:
discord.ext.commands.errors.CommandNotFound: Command "end" is not found
Ignoring exception in command None:
discord.ext.commands.errors.CommandNotFound: Command "timer" is not found
SSL error in data received
protocol: <asyncio.sslproto.SSLProtocol object at 0x73385330>
transport: <_SelectorSocketTransport fd=7 read=polling write=<idle, bufsize=0>>
Traceback (most recent call last):
  File "/usr/lib/python3.7/asyncio/sslproto.py", line 526, in data_received
    ssldata, appdata = self._sslpipe.feed_ssldata(data)
  File "/usr/lib/python3.7/asyncio/sslproto.py", line 207, in feed_ssldata
    self._sslobj.unwrap()
  File "/usr/lib/python3.7/ssl.py", line 767, in unwrap
    return self._sslobj.shutdown()
ssl.SSLError: [SSL: KRB5_S_INIT] application data after close notify (_ssl.c:2609)
Ignoring exception in command None:
discord.ext.commands.errors.CommandNotFound: Command "time" is not found
Ignoring exception in command None:
discord.ext.commands.errors.CommandNotFound: Command "checktimer" is not found
Ignoring exception in command None:
discord.ext.commands.errors.CommandNotFound: Command "wreck" is not found
Ignoring exception in command None:
discord.ext.commands.errors.CommandNotFound: Command "wreck" is not found
Ignoring exception in command None:
discord.ext.commands.errors.CommandNotFound: Command "checktimer" is not found
Ignoring exception in command None:
discord.ext.commands.errors.CommandNotFound: Command "~Bros~~Games" is not found
Ignoring exception in command None:
discord.ext.commands.errors.CommandNotFound: Command "Check" is not found
Ignoring exception in command None:
discord.ext.commands.errors.CommandNotFound: Command "Timer" is not found
Ignoring exception in command None:
discord.ext.commands.errors.CommandNotFound: Command "Time" is not found
~Logged in~
RentalBot
729469147037302895
~~~~~~~~~~~
~Logged in~
RentalBot
729469147037302895
~~~~~~~~~~~
~Logged in~
RentalBot
729469147037302895
~~~~~~~~~~~
Ignoring exception in command None:
discord.ext.commands.errors.CommandNotFound: Command "timestamp" is not found
Ignoring exception in command None:
discord.ext.commands.errors.CommandNotFound: Command "timestamp" is not found
Ignoring exception in command None:
discord.ext.commands.errors.CommandNotFound: Command "checktimer" is not found
Ignoring exception in command None:
discord.ext.commands.errors.CommandNotFound: Command "checktimer" is not found
Ignoring exception in command None:
discord.ext.commands.errors.CommandNotFound: Command "checktimer" is not found
~Logged in~
RentalBot
729469147037302895
~~~~~~~~~~~
  File "rentalbot.py", line 72
    async def on_ready():
        ^
SyntaxError: invalid syntax
SSL error in data received
protocol: <asyncio.sslproto.SSLProtocol object at 0x7481dbf0>
transport: <_SelectorSocketTransport fd=7 read=polling write=<idle, bufsize=0>>
Traceback (most recent call last):
  File "/usr/lib/python3.7/asyncio/sslproto.py", line 526, in data_received
    ssldata, appdata = self._sslpipe.feed_ssldata(data)
  File "/usr/lib/python3.7/asyncio/sslproto.py", line 207, in feed_ssldata
    self._sslobj.unwrap()
  File "/usr/lib/python3.7/ssl.py", line 767, in unwrap
    return self._sslobj.shutdown()
ssl.SSLError: [SSL: KRB5_S_INIT] application data after close notify (_ssl.c:2609)
SSL error in data received
protocol: <asyncio.sslproto.SSLProtocol object at 0x74827a90>
transport: <_SelectorSocketTransport fd=6 read=polling write=<idle, bufsize=0>>
Traceback (most recent call last):
  File "/usr/lib/python3.7/asyncio/sslproto.py", line 526, in data_received
    ssldata, appdata = self._sslpipe.feed_ssldata(data)
  File "/usr/lib/python3.7/asyncio/sslproto.py", line 207, in feed_ssldata
    self._sslobj.unwrap()
  File "/usr/lib/python3.7/ssl.py", line 767, in unwrap
    return self._sslobj.shutdown()
ssl.SSLError: [SSL: KRB5_S_INIT] application data after close notify (_ssl.c:2609)
SSL error in data received
protocol: <asyncio.sslproto.SSLProtocol object at 0x74889e50>
transport: <_SelectorSocketTransport fd=6 read=polling write=<idle, bufsize=0>>
Traceback (most recent call last):
  File "/usr/lib/python3.7/asyncio/sslproto.py", line 526, in data_received
    ssldata, appdata = self._sslpipe.feed_ssldata(data)
  File "/usr/lib/python3.7/asyncio/sslproto.py", line 207, in feed_ssldata
    self._sslobj.unwrap()
  File "/usr/lib/python3.7/ssl.py", line 767, in unwrap
    return self._sslobj.shutdown()
ssl.SSLError: [SSL: KRB5_S_INIT] application data after close notify (_ssl.c:2609)
SSL error in data received
protocol: <asyncio.sslproto.SSLProtocol object at 0x7485b550>
transport: <_SelectorSocketTransport fd=7 read=polling write=<idle, bufsize=0>>
Traceback (most recent call last):
  File "/usr/lib/python3.7/asyncio/sslproto.py", line 526, in data_received
    ssldata, appdata = self._sslpipe.feed_ssldata(data)
  File "/usr/lib/python3.7/asyncio/sslproto.py", line 207, in feed_ssldata
    self._sslobj.unwrap()
  File "/usr/lib/python3.7/ssl.py", line 767, in unwrap
    return self._sslobj.shutdown()
ssl.SSLError: [SSL: KRB5_S_INIT] application data after close notify (_ssl.c:2609)
SSL error in data received
protocol: <asyncio.sslproto.SSLProtocol object at 0x748919b0>
transport: <_SelectorSocketTransport fd=7 read=polling write=<idle, bufsize=0>>
Traceback (most recent call last):
  File "/usr/lib/python3.7/asyncio/sslproto.py", line 526, in data_received
    ssldata, appdata = self._sslpipe.feed_ssldata(data)
  File "/usr/lib/python3.7/asyncio/sslproto.py", line 207, in feed_ssldata
    self._sslobj.unwrap()
  File "/usr/lib/python3.7/ssl.py", line 767, in unwrap
    return self._sslobj.shutdown()
ssl.SSLError: [SSL: KRB5_S_INIT] application data after close notify (_ssl.c:2609)
SSL error in data received
protocol: <asyncio.sslproto.SSLProtocol object at 0x75a3e9d0>
transport: <_SelectorSocketTransport fd=7 read=polling write=<idle, bufsize=0>>
Traceback (most recent call last):
  File "/usr/lib/python3.7/asyncio/sslproto.py", line 526, in data_received
    ssldata, appdata = self._sslpipe.feed_ssldata(data)
  File "/usr/lib/python3.7/asyncio/sslproto.py", line 207, in feed_ssldata
    self._sslobj.unwrap()
  File "/usr/lib/python3.7/ssl.py", line 767, in unwrap
    return self._sslobj.shutdown()
ssl.SSLError: [SSL: KRB5_S_INIT] application data after close notify (_ssl.c:2609)
Ignoring exception in command None:
discord.ext.commands.errors.CommandNotFound: Command "time" is not found
Ignoring exception in command None:
discord.ext.commands.errors.CommandNotFound: Command "timer" is not found
~Logged in~
RentalBot
729469147037302895
~~~~~~~~~~~
~Logged in~
RentalBot
729469147037302895
~~~~~~~~~~~
~Logged in~
RentalBot
729469147037302895
~~~~~~~~~~~
~Logged in~
RentalBot
729469147037302895
~~~~~~~~~~~
~Logged in~
RentalBot
729469147037302895
~~~~~~~~~~~
~Logged in~
RentalBot
729469147037302895
~~~~~~~~~~~
~Logged in~
RentalBot
729469147037302895
~~~~~~~~~~~
~Logged in~
RentalBot
729469147037302895
~~~~~~~~~~~
~Logged in~
RentalBot
729469147037302895
~~~~~~~~~~~
~Logged in~
RentalBot
729469147037302895
~~~~~~~~~~~
Shadow Chain at 1
Ignoring exception in command None:
discord.ext.commands.errors.CommandNotFound: Command "checkavatar" is not found
SSL error in data received
protocol: <asyncio.sslproto.SSLProtocol object at 0x747a4070>
transport: <_SelectorSocketTransport fd=7 read=polling write=<idle, bufsize=0>>
Traceback (most recent call last):
  File "/usr/lib/python3.7/asyncio/sslproto.py", line 526, in data_received
    ssldata, appdata = self._sslpipe.feed_ssldata(data)
  File "/usr/lib/python3.7/asyncio/sslproto.py", line 207, in feed_ssldata
    self._sslobj.unwrap()
  File "/usr/lib/python3.7/ssl.py", line 767, in unwrap
    return self._sslobj.shutdown()
ssl.SSLError: [SSL: KRB5_S_INIT] application data after close notify (_ssl.c:2609)
SSL error in data received
protocol: <asyncio.sslproto.SSLProtocol object at 0x733979d0>
transport: <_SelectorSocketTransport fd=8 read=polling write=<idle, bufsize=0>>
Traceback (most recent call last):
  File "/usr/lib/python3.7/asyncio/sslproto.py", line 526, in data_received
    ssldata, appdata = self._sslpipe.feed_ssldata(data)
  File "/usr/lib/python3.7/asyncio/sslproto.py", line 207, in feed_ssldata
    self._sslobj.unwrap()
  File "/usr/lib/python3.7/ssl.py", line 767, in unwrap
    return self._sslobj.shutdown()
ssl.SSLError: [SSL: KRB5_S_INIT] application data after close notify (_ssl.c:2609)
SSL error in data received
protocol: <asyncio.sslproto.SSLProtocol object at 0x73397f90>
transport: <_SelectorSocketTransport fd=6 read=polling write=<idle, bufsize=0>>
Traceback (most recent call last):
  File "/usr/lib/python3.7/asyncio/sslproto.py", line 526, in data_received
    ssldata, appdata = self._sslpipe.feed_ssldata(data)
  File "/usr/lib/python3.7/asyncio/sslproto.py", line 207, in feed_ssldata
    self._sslobj.unwrap()
  File "/usr/lib/python3.7/ssl.py", line 767, in unwrap
    return self._sslobj.shutdown()
ssl.SSLError: [SSL: KRB5_S_INIT] application data after close notify (_ssl.c:2609)
SSL error in data received
protocol: <asyncio.sslproto.SSLProtocol object at 0x73397cf0>
transport: <_SelectorSocketTransport fd=7 read=polling write=<idle, bufsize=0>>
Traceback (most recent call last):
  File "/usr/lib/python3.7/asyncio/sslproto.py", line 526, in data_received
    ssldata, appdata = self._sslpipe.feed_ssldata(data)
  File "/usr/lib/python3.7/asyncio/sslproto.py", line 207, in feed_ssldata
    self._sslobj.unwrap()
  File "/usr/lib/python3.7/ssl.py", line 767, in unwrap
    return self._sslobj.shutdown()
ssl.SSLError: [SSL: KRB5_S_INIT] application data after close notify (_ssl.c:2609)
SSL error in data received
protocol: <asyncio.sslproto.SSLProtocol object at 0x73d68510>
transport: <_SelectorSocketTransport fd=8 read=polling write=<idle, bufsize=0>>
Traceback (most recent call last):
  File "/usr/lib/python3.7/asyncio/sslproto.py", line 526, in data_received
    ssldata, appdata = self._sslpipe.feed_ssldata(data)
  File "/usr/lib/python3.7/asyncio/sslproto.py", line 207, in feed_ssldata
    self._sslobj.unwrap()
  File "/usr/lib/python3.7/ssl.py", line 767, in unwrap
    return self._sslobj.shutdown()
ssl.SSLError: [SSL: KRB5_S_INIT] application data after close notify (_ssl.c:2609)
SSL error in data received
protocol: <asyncio.sslproto.SSLProtocol object at 0x747a4b10>
transport: <_SelectorSocketTransport fd=7 read=polling write=<idle, bufsize=0>>
Traceback (most recent call last):
  File "/usr/lib/python3.7/asyncio/sslproto.py", line 526, in data_received
    ssldata, appdata = self._sslpipe.feed_ssldata(data)
  File "/usr/lib/python3.7/asyncio/sslproto.py", line 207, in feed_ssldata
    self._sslobj.unwrap()
  File "/usr/lib/python3.7/ssl.py", line 767, in unwrap
    return self._sslobj.shutdown()
ssl.SSLError: [SSL: KRB5_S_INIT] application data after close notify (_ssl.c:2609)
SSL error in data received
protocol: <asyncio.sslproto.SSLProtocol object at 0x73db9b30>
transport: <_SelectorSocketTransport fd=6 read=polling write=<idle, bufsize=0>>
Traceback (most recent call last):
  File "/usr/lib/python3.7/asyncio/sslproto.py", line 526, in data_received
    ssldata, appdata = self._sslpipe.feed_ssldata(data)
  File "/usr/lib/python3.7/asyncio/sslproto.py", line 207, in feed_ssldata
    self._sslobj.unwrap()
  File "/usr/lib/python3.7/ssl.py", line 767, in unwrap
    return self._sslobj.shutdown()
ssl.SSLError: [SSL: KRB5_S_INIT] application data after close notify (_ssl.c:2609)
Ignoring exception in on_message
Traceback (most recent call last):
  File "/home/pi/.local/lib/python3.7/site-packages/discord/client.py", line 333, in _run_event
    await coro(*args, **kwargs)
  File "rentalbot.py", line 110, in on_message
    if (message.channel.name == "gen-pop" and len(messageContent) > 0):
AttributeError: 'DMChannel' object has no attribute 'name'
Ignoring exception in on_message
Traceback (most recent call last):
  File "/home/pi/.local/lib/python3.7/site-packages/discord/client.py", line 333, in _run_event
    await coro(*args, **kwargs)
  File "rentalbot.py", line 110, in on_message
    if (message.channel.name == "gen-pop" and len(messageContent) > 0):
AttributeError: 'DMChannel' object has no attribute 'name'
Ignoring exception in command None:
discord.ext.commands.errors.CommandNotFound: Command "checktime" is not found
~Logged in~
RentalBot
729469147037302895
~~~~~~~~~~~
Shadow Chain at 1
Shadow Chain at 2
Shadow Chain at 3
Shadow Chain at 4
Shadow chain broken at 4 Shadows
Shadow Chain at 1
Shadow Chain at 2
Shadow chain broken at 2 Shadows
Shadow Chain at 1
~Logged in~
RentalBot
729469147037302895
~~~~~~~~~~~
Shadow Chain at 1
Shadow Chain at 1
Shadow Chain at 1
Shadow Chain at 1
Shadow Chain at 2
Shadow Chain at 3
Shadow chain broken at 3 Shadows
Shadow Chain at 1
Shadow Chain at 2
Shadow chain broken at 2 Shadows
Shadow Chain at 1
Shadow Chain at 2
Shadow chain broken at 2 Shadows
Shadow Chain at 1
Shadow Chain at 2
Shadow Chain at 3
Shadow Chain at 4
Shadow chain broken at 4 Shadows
Shadow Chain at 1
Ignoring exception in command None:
discord.ext.commands.errors.CommandNotFound: Command "count" is not found
Ignoring exception in command None:
discord.ext.commands.errors.CommandNotFound: Command "hot" is not found
Ignoring exception in command None:
discord.ext.commands.errors.CommandNotFound: Command "checktimer" is not found
Ignoring exception in command None:
discord.ext.commands.errors.CommandNotFound: Command "checktimer" is not found
Ignoring exception in command None:
discord.ext.commands.errors.CommandNotFound: Command "offer" is not found
Ignoring exception in command None:
discord.ext.commands.errors.CommandNotFound: Command "checktimer" is not found
Ignoring exception in command None:
discord.ext.commands.errors.CommandNotFound: Command "slap" is not found
Ignoring exception in command None:
discord.ext.commands.errors.CommandNotFound: Command "dadjoke" is not found
Ignoring exception in command None:
discord.ext.commands.errors.CommandNotFound: Command "slap" is not found
~Logged in~
RentalBot
729469147037302895
~~~~~~~~~~~
Shadow Chain at 1
Shadow Chain at 2
Shadow Chain at 3
Shadow Chain at 4
Shadow chain broken at 4 Shadows
~Logged in~
RentalBot
729469147037302895
~~~~~~~~~~~
~Logged in~
RentalBot
729469147037302895
~~~~~~~~~~~
Shadow Chain at 1
Shadow Chain at 2
Shadow Chain at 3
Shadow Chain at 4
Shadow Chain at 5
Shadow Chain at 6
Shadow Chain at 7
Shadow Chain at 8
Shadow Chain at 9
Shadow Chain at 10
Shadow Chain at 11
Shadow Chain at 12
Shadow Chain at 13
Shadow Chain at 14
Shadow Chain at 15
Shadow Chain at 16
Shadow Chain at 17
Shadow Chain at 18
Shadow Chain at 19
Shadow Chain at 20
Shadow Chain at 21
Shadow Chain at 22
Shadow Chain at 23
Shadow Chain at 24
Shadow Chain at 25
Shadow Chain at 26
Shadow Chain at 27
Shadow Chain at 28
Shadow Chain at 29
Shadow Chain at 30
Shadow Chain at 31
Shadow chain broken at 31 Shadows
Shadow Chain at 1
Shadow Chain at 1
Shadow Chain at 1
Shadow Chain at 2
Shadow Chain at 3
Shadow Chain at 4
Shadow chain broken at 4 Shadows
Shadow Chain at 1
Shadow Chain at 2
Shadow Chain at 3
Shadow Chain at 4
Shadow Chain at 5
Shadow Chain at 6
Shadow Chain at 7
Shadow chain broken at 7 Shadows
Shadow Chain at 1
Shadow Chain at 1
Shadow Chain at 1
Shadow Chain at 2
Shadow chain broken at 2 Shadows
Shadow Chain at 1
Shadow Chain at 1
~Logged in~
RentalBot
729469147037302895
~~~~~~~~~~~
Ignoring exception in command None:
discord.ext.commands.errors.CommandNotFound: Command "Check" is not found
Ignoring exception in command None:
discord.ext.commands.errors.CommandNotFound: Command "timer" is not found
Ignoring exception in command None:
discord.ext.commands.errors.CommandNotFound: Command "_>" is not found
Ignoring exception in command None:
discord.ext.commands.errors.CommandNotFound: Command "checktimer" is not found
~Logged in~
RentalBot
729469147037302895
~~~~~~~~~~~
Shadow Chain at 1
~Logged in~
RentalBot
729469147037302895
~~~~~~~~~~~
Ignoring exception in command None:
discord.ext.commands.errors.CommandNotFound: Command "Check" is not found
~Logged in~
RentalBot
729469147037302895
~~~~~~~~~~~
Traceback (most recent call last):
  File "/home/pi/.local/lib/python3.7/site-packages/discord/http.py", line 291, in static_login
    data = await self.request(Route('GET', '/users/@me'))
  File "/home/pi/.local/lib/python3.7/site-packages/discord/http.py", line 245, in request
    raise HTTPException(r, data)
discord.errors.HTTPException: 401 Unauthorized (error code: 0): 401: Unauthorized

The above exception was the direct cause of the following exception:

Traceback (most recent call last):
  File "rentalbot.py", line 303, in <module>
    client.run(token)
  File "/home/pi/.local/lib/python3.7/site-packages/discord/client.py", line 708, in run
    return future.result()
  File "/home/pi/.local/lib/python3.7/site-packages/discord/client.py", line 687, in runner
    await self.start(*args, **kwargs)
  File "/home/pi/.local/lib/python3.7/site-packages/discord/client.py", line 650, in start
    await self.login(*args, bot=bot)
  File "/home/pi/.local/lib/python3.7/site-packages/discord/client.py", line 499, in login
    await self.http.static_login(token.strip(), bot=bot)
  File "/home/pi/.local/lib/python3.7/site-packages/discord/http.py", line 295, in static_login
    raise LoginFailure('Improper token has been passed.') from exc
discord.errors.LoginFailure: Improper token has been passed.
Traceback (most recent call last):
  File "/home/pi/.local/lib/python3.7/site-packages/discord/http.py", line 291, in static_login
    data = await self.request(Route('GET', '/users/@me'))
  File "/home/pi/.local/lib/python3.7/site-packages/discord/http.py", line 245, in request
    raise HTTPException(r, data)
discord.errors.HTTPException: 401 Unauthorized (error code: 0): 401: Unauthorized

The above exception was the direct cause of the following exception:

Traceback (most recent call last):
  File "rentalbot.py", line 303, in <module>
    client.run(token)
  File "/home/pi/.local/lib/python3.7/site-packages/discord/client.py", line 708, in run
    return future.result()
  File "/home/pi/.local/lib/python3.7/site-packages/discord/client.py", line 687, in runner
    await self.start(*args, **kwargs)
  File "/home/pi/.local/lib/python3.7/site-packages/discord/client.py", line 650, in start
    await self.login(*args, bot=bot)
  File "/home/pi/.local/lib/python3.7/site-packages/discord/client.py", line 499, in login
    await self.http.static_login(token.strip(), bot=bot)
  File "/home/pi/.local/lib/python3.7/site-packages/discord/http.py", line 295, in static_login
    raise LoginFailure('Improper token has been passed.') from exc
discord.errors.LoginFailure: Improper token has been passed.
